Workbook

Sheet Attainment-main
C1: D Y Patil International University, Akurdi Pune
C2: Name of School
A4: Programme Outcome attainment through Direct Attainment Method
A6: Subject Name : | C6: Computer Network and Security
A7: Academic Year : | C7: AY 2023-24
A8: Semester : | C8: I
A9: Subject Code : | C9: 310244
A10: Faculty Name: | C10: XYZ
A12: Course Outcome
A13: Sr No | B13: Code | C13: Statement
A14: 1 | B14: C321.1 | C14: Interpret fundamental concepts of Computer Networks, architectures, protocols and technologies
A15: 2 | B15: C321.2 | C15: Demonstrate the working and functions of data link layer for flow and error control
A16: 3 | B16: C321.3 | C16: Analyze the working of different routing protocols and mechanisms for transmission of data
A17: 4 | B17: C321.4 | C17: Implement client-server applications using sockets
A18: 5 | B18: C321.5 | C18: Analyze role of application layer with its protocols, client-server architectures
A19: 6 | B19: C321.6 | C19: Interpret the basics of Network Security for secured communication
A21: Table 1 : Mapping of CO to PO/PSO
A22: Sr No | B22: Code | C22: PO1 | D22: PO2 | E22: PO3 | F22: PO4 | G22: PO5 | H22: PO6 | I22: PO7 | J22: PO8 | K22: PO9 | L22: PO10 | M22: PO11 | N22: PO12 | O22: PSO1 | P22: PSO2 | Q22: PSO3
A23: 1 | B23: =B14 -> C321.1 | C23: 3 | D23: 3 | E23: 2 | F23: 2 | G23: - | H23: - | I23: - | J23: - | K23: - | L23: - | M23: - | N23: - | O23: 3 | P23: 2 | Q23: -
A24: 2 | B24: =B15 -> C321.2 | C24: 3 | D24: 3 | E24: 3 | F24: 2 | G24: - | H24: - | I24: - | J24: - | K24: - | L24: - | M24: - | N24: - | O24: 3 | P24: 2 | Q24: -
A25: 3 | B25: =B16 -> C321.3 | C25: 3 | D25: 3 | E25: 3 | F25: 1 | G25: - | H25: - | I25: - | J25: - | K25: - | L25: - | M25: - | N25: - | O25: 3 | P25: 2 | Q25: -
A26: 4 | B26: =B17 -> C321.4 | C26: 1 | D26: 2 | E26: 2 | F26: 1 | G26: - | H26: - | I26: - | J26: - | K26: - | L26: - | M26: - | N26: - | O26: 3 | P26: 2 | Q26: -
A27: 5 | B27: =B18 -> C321.5 | C27: 1 | D27: 2 | E27: 2 | F27: 1 | G27: - | H27: - | I27: - | J27: - | K27: - | L27: - | M27: - | N27: 1 | O27: 3 | P27: 2 | Q27: 1
A28: 6 | B28: =B19 -> C321.6 | C28: 1 | D28: 3 | E28: 1 | F28: 1 | G28: - | H28: - | I28: - | J28: - | K28: - | L28: - | M28: - | N28: 1 | O28: 3 | P28: 2 | Q28: 1
A29: Average | C29: =IFERROR(AVERAGE(C23:C28),"-") -> 2 | D29: =IFERROR(AVERAGE(D23:D28),"-") -> 2.6666667 | E29: =IFERROR(AVERAGE(E23:E28),"-") -> 2.1666667 | F29: =IFERROR(AVERAGE(F23:F28),"-") -> 1.3333333 | G29: =IFERROR(AVERAGE(G23:G28),"-") -> - | H29: =IFERROR(AVERAGE(H23:H28),"-") -> - | I29: =IFERROR(AVERAGE(I23:I28),"-") -> - | J29: =IFERROR(AVERAGE(J23:J28),"-") -> - | ... Q29: =IFERROR(AVERAGE(Q23:Q28),"-") -> 1
A31: Overall CO Attainment | D31: Get from below reference work
A32: =D48 -> 2.0666667
A34: Table 2: PO Attainment Values (Direct Attainment)
A35: Code | C35: PO1 | D35: PO2 | E35: PO3 | F35: PO4 | G35: PO5 | H35: PO6 | I35: PO7 | J35: PO8 | K35: PO9 | L35: PO10 | M35: PO11 | N35: PO12 | O35: PSO1 | P35: PSO2 | Q35: PSO3
A36: =C9 -> 310244 | C36: =IF(C29<>"-",C29*$A$32/3,"-") -> 1.3777778 | D36: =IF(D29<>"-",D29*$A$32/3,"-") -> 1.837037 | E36: =IF(E29<>"-",E29*$A$32/3,"-") -> 1.4925926 | F36: =IF(F29<>"-",F29*$A$32/3,"-") -> 0.91851852 | G36: =IF(G29<>"-",G29*$A$32/3,"-") -> - | H36: =IF(H29<>"-",H29*$A$32/3,"-") -> - | I36: =IF(I29<>"-",I29*$A$32/3,"-") -> - | J36: =IF(J29<>"-",J29*$A$32/3,"-") -> - | ... Q36: =IF(Q29<>"-",Q29*$A$32/3,"-") -> 0.68888889
A39: Reference Work
D40: CO1 | E40: CO2 | F40: CO3 | G40: CO4 | H40: CO5 | I40: CO6
A41: % of students above threshold | C41: Direct through Examination | D41: =Examination!F17 -> 45.833333 | E41: =Examination!G17 -> 33.333333 | F41: =Examination!H17 -> 45.833333 | G41: =Examination!I17 -> 25 | H41: =Examination!J17 -> 79.166667 | I41: =Examination!K17 -> 50 | J41: Get values from Examination sheet
A42: Attainment | D42: =IF((D41>=60),3,IF(AND(D41>=40,D41<60),2,IF(AND(D41>0,D41<40),1,""))) -> 2 | E42: =IF((E41>=60),3,IF(AND(E41>=40,E41<60),2,IF(AND(E41>0,E41<40),1,""))) -> 1 | F42: =IF((F41>=60),3,IF(AND(F41>=40,F41<60),2,IF(AND(F41>0,F41<40),1,""))) -> 2 | G42: =IF((G41>=60),3,IF(AND(G41>=40,G41<60),2,IF(AND(G41>0,G41<40),1,""))) -> 1 | H42: =IF((H41>=60),3,IF(AND(H41>=40,H41<60),2,IF(AND(H41>0,H41<40),1,""))) -> 3 | I42: =IF((I41>=60),3,IF(AND(I41>=40,I41<60),2,IF(AND(I41>0,I41<40),1,""))) -> 2
A43: % of students above threshold | C43: Indirect through Course End Survey | D43: ='Course End Survey'!C15 -> 87.625 | E43: ='Course End Survey'!D15 -> 73.625 | F43: ='Course End Survey'!E15 -> 76.375 | G43: ='Course End Survey'!F15 -> 69.291667 | H43: ='Course End Survey'!G15 -> 89 | I43: ='Course End Survey'!H15 -> 90.375 | J43: Get values from Course End sheet
A44: Attainment | D44: =IF((D43>=60),3,IF(AND(D43>=40,D43<60),2,IF(AND(D43>0,D43<40),1,""))) -> 3 | E44: =IF((E43>=60),3,IF(AND(E43>=40,E43<60),2,IF(AND(E43>0,E43<40),1,""))) -> 3 | F44: =IF((F43>=60),3,IF(AND(F43>=40,F43<60),2,IF(AND(F43>0,F43<40),1,""))) -> 3 | G44: =IF((G43>=60),3,IF(AND(G43>=40,G43<60),2,IF(AND(G43>0,G43<40),1,""))) -> 3 | H44: =IF((H43>=60),3,IF(AND(H43>=40,H43<60),2,IF(AND(H43>0,H43<40),1,""))) -> 3 | I44: =IF((I43>=60),3,IF(AND(I43>=40,I43<60),2,IF(AND(I43>0,I43<40),1,""))) -> 3
A46: Attainment of CO | D46: =D42*0.8+D44*0.2 -> 2.2 | E46: =E42*0.8+E44*0.2 -> 1.4 | F46: =F42*0.8+F44*0.2 -> 2.2 | G46: =G42*0.8+G44*0.2 -> 1.4 | H46: =H42*0.8+H44*0.2 -> 3 | I46: =I42*0.8+I44*0.2 -> 2.2
A48: Overall CO Attainment | D48: =AVERAGE(D46:I46) -> 2.0666667

Sheet PO mapping
A4: Justification 1 | D4: Keywords mapping to Competency from resepctive CO | K4: Y or N
A5: Programme Outcomes | B5: Competency | D5: CO1 | E5: CO2 | F5: CO3 | G5: CO4 | H5: CO5 | I5: CO6 | K5: CO1 | L5: CO2 | M5: CO3 | N5: CO4 | O5: CO5 | P5: CO6
A6: 1. Apply the knowledge of mathematics, science, engineering fundamentals and engineering specialization to the solution of complex engineering problems | B6: Demonstrate competence in knowledge of basic & applied mathematics | D6: Line coding | E6: Parity bits | F6: IP addresing | G6: addressing | K6: =IF(D6="","","Y") -> Y | L6: =IF(E6="","","Y") -> Y | M6: =IF(F6="","","Y") -> Y | N6: =IF(G6="","","Y") -> Y | O6: =IF(H6="","","Y") | P6: =IF(I6="","","Y")
B7: Demonstrate competence in basic sciences | D7: fibre optics transmission | K7: =IF(D7="","","Y") -> Y | L7: =IF(E7="","","Y") | M7: =IF(F7="","","Y") | N7: =IF(G7="","","Y") | O7: =IF(H7="","","Y") | P7: =IF(I7="","","Y")
B8: Demonstrate competence in engineering fundamentals | D8: design issues | E8: connectivity | F8: Protocols | G8: connection protocols | K8: =IF(D8="","","Y") -> Y | L8: =IF(E8="","","Y") -> Y | M8: =IF(F8="","","Y") -> Y | N8: =IF(G8="","","Y") -> Y | O8: =IF(H8="","","Y") | P8: =IF(I8="","","Y")
B9: Demonstrate competence in specialized engineering knowledge to the program | D9: types, models. Architecture | E9: flowcontrol, IEEE standards | F9: IEEE standards | G9: routing | H9: Applications | I9: Security | K9: =IF(D9="","","Y") -> Y | L9: =IF(E9="","","Y") -> Y | M9: =IF(F9="","","Y") -> Y | N9: =IF(G9="","","Y") -> Y | O9: =IF(H9="","","Y") -> Y | P9: =IF(I9="","","Y") -> Y
D10: No of competencies from given PO1 mapped by COs | K10: =COUNTIF(K6:K9,"Y") -> 4 | L10: =COUNTIF(L6:L9,"Y") -> 3 | M10: =COUNTIF(M6:M9,"Y") -> 3 | N10: =COUNTIF(N6:N9,"Y") -> 3 | O10: =COUNTIF(O6:O9,"Y") -> 1 | P10: =COUNTIF(P6:P9,"Y") -> 1
D11: % of competencies from given PO1 mapped by COs | K11: =100*K10/4 -> 100 | L11: =100*L10/4 -> 75 | M11: =100*M10/4 -> 75 | N11: =100*N10/4 -> 75 | O11: =100*O10/4 -> 25 | P11: =100*P10/4 -> 25
D12: Mapping strength of PO1 of CO | K12: =IF((K11>=66),3,IF(AND(K11>=33,K11<66),2,IF(AND(K11>0,K11<33),1,"-"))) -> 3 | L12: =IF((L11>=66),3,IF(AND(L11>=33,L11<66),2,IF(AND(L11>0,L11<33),1,"-"))) -> 3 | M12: =IF((M11>=66),3,IF(AND(M11>=33,M11<66),2,IF(AND(M11>0,M11<33),1,"-"))) -> 3 | N12: =IF((N11>=66),3,IF(AND(N11>=33,N11<66),2,IF(AND(N11>0,N11<33),1,"-"))) -> 3 | O12: =IF((O11>=66),3,IF(AND(O11>=33,O11<66),2,IF(AND(O11>0,O11<33),1,"-"))) -> 1 | P12: =IF((P11>=66),3,IF(AND(P11>=33,P11<66),2,IF(AND(P11>0,P11<33),1,"-"))) -> 1
A13: 2. Identify, formulate, review research literature, and analyze complex computer engineering problems reaching substantiated conclusions using first principals of mathematic, natural sciences, and engineering sciences | B13: Demonstrate an ability to identify and formulate complex engineering problem | D13: Line encoding | E13: flow control | F13: addressing | G13: flow control | H13: Applications | I13: security | K13: =IF(D13="","","Y") -> Y | L13: =IF(E13="","","Y") -> Y | M13: =IF(F13="","","Y") -> Y | N13: =IF(G13="","","Y") -> Y | O13: =IF(H13="","","Y") -> Y | P13: =IF(I13="","","Y") -> Y
B14: Demonstrate an ability to formulate a solution plan and methodology for an engineering problem | D14: architecture | E14: design issues | F14: routing | G14: protocols | H14: Applications | I14: cryptography | K14: =IF(D14="","","Y") -> Y | L14: =IF(E14="","","Y") -> Y | M14: =IF(F14="","","Y") -> Y | N14: =IF(G14="","","Y") -> Y | O14: =IF(H14="","","Y") -> Y | P14: =IF(I14="","","Y") -> Y
B15: Demonstrate an ability to formulate and interpret a model | D15: models | E15: sliding window protocol | F15: QoS | I15: IPSec | K15: =IF(D15="","","Y") -> Y | L15: =IF(E15="","","Y") -> Y | M15: =IF(F15="","","Y") -> Y | N15: =IF(G15="","","Y") | O15: =IF(H15="","","Y") | P15: =IF(I15="","","Y") -> Y
B16: Demonstrate an ability to execute a solution process and analyze results | E16: error control codes | I16: SSL | K16: =IF(D16="","","Y") | L16: =IF(E16="","","Y") -> Y | M16: =IF(F16="","","Y") | N16: =IF(G16="","","Y") | O16: =IF(H16="","","Y") | P16: =IF(I16="","","Y") -> Y
D17: No of competencies from given PO2 mapped by COs | K17: =COUNTIF(K13:K16,"Y") -> 3 | L17: =COUNTIF(L13:L16,"Y") -> 4 | M17: =COUNTIF(M13:M16,"Y") -> 3 | N17: =COUNTIF(N13:N16,"Y") -> 2 | O17: =COUNTIF(O13:O16,"Y") -> 2 | P17: =COUNTIF(P13:P16,"Y") -> 4
D18: % of competencies from given PO2 mapped by COs | K18: =100*K17/4 -> 75 | L18: =100*L17/4 -> 100 | M18: =100*M17/4 -> 75 | N18: =100*N17/4 -> 50 | O18: =100*O17/4 -> 50 | P18: =100*P17/4 -> 100
D19: Mapping strength of PO2 of CO | K19: =IF((K18>=66),3,IF(AND(K18>=33,K18<66),2,IF(AND(K18>0,K18<33),1,"-"))) -> 3 | L19: =IF((L18>=66),3,IF(AND(L18>=33,L18<66),2,IF(AND(L18>0,L18<33),1,"-"))) -> 3 | M19: =IF((M18>=66),3,IF(AND(M18>=33,M18<66),2,IF(AND(M18>0,M18<33),1,"-"))) -> 3 | N19: =IF((N18>=66),3,IF(AND(N18>=33,N18<66),2,IF(AND(N18>0,N18<33),1,"-"))) -> 2 | O19: =IF((O18>=66),3,IF(AND(O18>=33,O18<66),2,IF(AND(O18>0,O18<33),1,"-"))) -> 2 | P19: =IF((P18>=66),3,IF(AND(P18>=33,P18<66),2,IF(AND(P18>0,P18<33),1,"-"))) -> 3
A20: 3. Design solutions for complex computer engineering problems and design system components or process that meet the specialized need with appropriate consideration for the public health and safety and the cultural, societal, and environmental considerations | B20: Demonstrate an ability to define a complex/open-ended problem in engineering terms | E20: design issues | F20: addressing | G20: connection | H20: Applications | I20: Network security | K20: =IF(D20="","","Y") | L20: =IF(E20="","","Y") -> Y | M20: =IF(F20="","","Y") -> Y | N20: =IF(G20="","","Y") -> Y | O20: =IF(H20="","","Y") -> Y | P20: =IF(I20="","","Y") -> Y
B21: Demonstrate an ability to generate a diverse set of alternative design solutions | D21: encoding | E21: codes | F21: routing | K21: =IF(D21="","","Y") -> Y | L21: =IF(E21="","","Y") -> Y | M21: =IF(F21="","","Y") -> Y | N21: =IF(G21="","","Y") | O21: =IF(H21="","","Y") | P21: =IF(I21="","","Y")
B22: Demonstrate an ability to select optimal design scheme for further development | D22: design | E22: codes | F22: congestion control | G22: QoS | H22: Applications | K22: =IF(D22="","","Y") -> Y | L22: =IF(E22="","","Y") -> Y | M22: =IF(F22="","","Y") -> Y | N22: =IF(G22="","","Y") -> Y | O22: =IF(H22="","","Y") -> Y | P22: =IF(I22="","","Y")
B23: Demonstrate an ability to advance an engineering design to defined end state | K23: =IF(D23="","","Y") | L23: =IF(E23="","","Y") | M23: =IF(F23="","","Y") | N23: =IF(G23="","","Y") | O23: =IF(H23="","","Y") | P23: =IF(I23="","","Y")
D24: No of competencies from given PO3 mapped by COs | K24: =COUNTIF(K20:K23,"Y") -> 2 | L24: =COUNTIF(L20:L23,"Y") -> 3 | M24: =COUNTIF(M20:M23,"Y") -> 3 | N24: =COUNTIF(N20:N23,"Y") -> 2 | O24: =COUNTIF(O20:O23,"Y") -> 2 | P24: =COUNTIF(P20:P23,"Y") -> 1
D25: % of competencies from given PO3 mapped by COs | K25: =100*K24/4 -> 50 | L25: =100*L24/4 -> 75 | M25: =100*M24/4 -> 75 | N25: =100*N24/4 -> 50 | O25: =100*O24/4 -> 50 | P25: =100*P24/4 -> 25
D26: Mapping strength of PO3 of CO | K26: =IF((K25>=66),3,IF(AND(K25>=33,K25<66),2,IF(AND(K25>0,K25<33),1,"-"))) -> 2 | L26: =IF((L25>=66),3,IF(AND(L25>=33,L25<66),2,IF(AND(L25>0,L25<33),1,"-"))) -> 3 | M26: =IF((M25>=66),3,IF(AND(M25>=33,M25<66),2,IF(AND(M25>0,M25<33),1,"-"))) -> 3 | N26: =IF((N25>=66),3,IF(AND(N25>=33,N25<66),2,IF(AND(N25>0,N25<33),1,"-"))) -> 2 | O26: =IF((O25>=66),3,IF(AND(O25>=33,O25<66),2,IF(AND(O25>0,O25<33),1,"-"))) -> 2 | P26: =IF((P25>=66),3,IF(AND(P25>=33,P25<66),2,IF(AND(P25>0,P25<33),1,"-"))) -> 1
A27: 4. Use research based knowledge and research methods including design of experiments, analysis and interpretation of data and synthesis of the information to provide valid conclusions. | B27: Demonstrate an ability to conduct investigations of technical issues consistent with their level of knowledge | D27: layered protocol model | E27: logical link control design issues | K27: =IF(D27="","","Y") -> Y | L27: =IF(E27="","","Y") -> Y | M27: =IF(F27="","","Y") | N27: =IF(G27="","","Y") | O27: =IF(H27="","","Y") | P27: =IF(I27="","","Y")
B28: Demonstrate an ability to design experiments to solve open-ended problems | D28: organizational structure | E28: media access contention | H28: Real time applications | I28: Network security | K28: =IF(D28="","","Y") -> Y | L28: =IF(E28="","","Y") -> Y | M28: =IF(F28="","","Y") | N28: =IF(G28="","","Y") | O28: =IF(H28="","","Y") -> Y | P28: =IF(I28="","","Y") -> Y
B29: Demonstrate an ability to analyze data and reach a valid conclusion | F29: assignment of IP addresses | G29: architectures and prototypes | K29: =IF(D29="","","Y") | L29: =IF(E29="","","Y") | M29: =IF(F29="","","Y") -> Y | N29: =IF(G29="","","Y") -> Y | O29: =IF(H29="","","Y") | P29: =IF(I29="","","Y")
D30: No of competencies from given PO4 mapped by COs | K30: =COUNTIF(K26:K29,"Y") -> 2 | L30: =COUNTIF(L26:L29,"Y") -> 2 | M30: =COUNTIF(M26:M29,"Y") -> 1 | N30: =COUNTIF(N26:N29,"Y") -> 1 | O30: =COUNTIF(O26:O29,"Y") -> 1 | P30: =COUNTIF(P26:P29,"Y") -> 1
D31: % of competencies from given PO4 mapped by COs | K31: =100*K30/4 -> 50 | L31: =100*L30/4 -> 50 | M31: =100*M30/4 -> 25 | N31: =100*N30/4 -> 25 | O31: =100*O30/4 -> 25 | P31: =100*P30/4 -> 25
D32: Mapping strength of PO4 of CO | K32: =IF((K31>=66),3,IF(AND(K31>=33,K31<66),2,IF(AND(K31>0,K31<33),1,"-"))) -> 2 | L32: =IF((L31>=66),3,IF(AND(L31>=33,L31<66),2,IF(AND(L31>0,L31<33),1,"-"))) -> 2 | M32: =IF((M31>=66),3,IF(AND(M31>=33,M31<66),2,IF(AND(M31>0,M31<33),1,"-"))) -> 1 | N32: =IF((N31>=66),3,IF(AND(N31>=33,N31<66),2,IF(AND(N31>0,N31<33),1,"-"))) -> 1 | O32: =IF((O31>=66),3,IF(AND(O31>=33,O31<66),2,IF(AND(O31>0,O31<33),1,"-"))) -> 1 | P32: =IF((P31>=66),3,IF(AND(P31>=33,P31<66),2,IF(AND(P31>0,P31<33),1,"-"))) -> 1
A33: 5. Create, select and apply appropriate techniques, resources, and modern engineering and IT tools including prediction and modeling to complex computer engineering activities with an understanding of the limitations. | B33: Demonstrate an ability to identify/create modern engineering tools, techniques and resources | K33: =IF(D33="","","Y") | L33: =IF(E33="","","Y") | M33: =IF(F33="","","Y") | N33: =IF(G33="","","Y") | O33: =IF(H33="","","Y") | P33: =IF(I33="","","Y")
B34: Demonstrate an ability to select and apply disciplinespecific tools, techniques and resources | K34: =IF(D34="","","Y") | L34: =IF(E34="","","Y") | M34: =IF(F34="","","Y") | N34: =IF(G34="","","Y") | O34: =IF(H34="","","Y") | P34: =IF(I34="","","Y")
B35: Demonstrate an ability to evaluate the suitability and limitations of tools used to solve an engineering problem | K35: =IF(D35="","","Y") | L35: =IF(E35="","","Y") | M35: =IF(F35="","","Y") | N35: =IF(G35="","","Y") | O35: =IF(H35="","","Y") | P35: =IF(I35="","","Y")
D36: No of competencies from given PO5 mapped by COs | K36: =COUNTIF(K32:K35,"Y") -> 0 | L36: =COUNTIF(L32:L35,"Y") -> 0 | M36: =COUNTIF(M32:M35,"Y") -> 0 | N36: =COUNTIF(N32:N35,"Y") -> 0 | O36: =COUNTIF(O32:O35,"Y") -> 0 | P36: =COUNTIF(P32:P35,"Y") -> 0
D37: % of competencies from given PO5 mapped by COs | K37: =100*K36/4 -> 0 | L37: =100*L36/4 -> 0 | M37: =100*M36/4 -> 0 | N37: =100*N36/4 -> 0 | O37: =100*O36/4 -> 0 | P37: =100*P36/4 -> 0
D38: Mapping strength of PO5 of CO | K38: =IF((K37>=66),3,IF(AND(K37>=33,K37<66),2,IF(AND(K37>0,K37<33),1,"-"))) -> - | L38: =IF((L37>=66),3,IF(AND(L37>=33,L37<66),2,IF(AND(L37>0,L37<33),1,"-"))) -> - | M38: =IF((M37>=66),3,IF(AND(M37>=33,M37<66),2,IF(AND(M37>0,M37<33),1,"-"))) -> - | N38: =IF((N37>=66),3,IF(AND(N37>=33,N37<66),2,IF(AND(N37>0,N37<33),1,"-"))) -> - | O38: =IF((O37>=66),3,IF(AND(O37>=33,O37<66),2,IF(AND(O37>0,O37<33),1,"-"))) -> - | P38: =IF((P37>=66),3,IF(AND(P37>=33,P37<66),2,IF(AND(P37>0,P37<33),1,"-"))) -> -
A39: 6. Apply reasoning informed by the contextual knowledge to assess societal, health, safety, legal, and cultural issues and the consequent responsibilities relevant to the professional engineering practice | B39: Demonstrate an ability to describe engineering roles in a broader context, e.g. pertaining to the environment, health, safety, legal and public welfare | K39: =IF(D39="","","Y") | L39: =IF(E39="","","Y") | M39: =IF(F39="","","Y") | N39: =IF(G39="","","Y") | O39: =IF(H39="","","Y") | P39: =IF(I39="","","Y")
B40: Demonstrate an understanding of professional engineering regulations, legislation and standards | K40: =IF(D40="","","Y") | L40: =IF(E40="","","Y") | M40: =IF(F40="","","Y") | N40: =IF(G40="","","Y") | O40: =IF(H40="","","Y") | P40: =IF(I40="","","Y")
D41: No of competencies from given PO6 mapped by COs | K41: =COUNTIF(K39:K40,"Y") -> 0 | L41: =COUNTIF(L39:L40,"Y") -> 0 | M41: =COUNTIF(M39:M40,"Y") -> 0 | N41: =COUNTIF(N39:N40,"Y") -> 0 | O41: =COUNTIF(O39:O40,"Y") -> 0 | P41: =COUNTIF(P39:P40,"Y") -> 0
D42: % of competencies from given PO6 mapped by COs | K42: =100*K41/2 -> 0 | L42: =100*L41/2 -> 0 | M42: =100*M41/2 -> 0 | N42: =100*N41/2 -> 0 | O42: =100*O41/2 -> 0 | P42: =100*P41/2 -> 0
D43: Mapping strength of PO6 of CO | K43: =IF((K42>50),3,IF(AND(K42>0,K42<=50),1,IF(AND(K42=0,K42<0),"-","-"))) -> - | L43: =IF((L42>50),3,IF(AND(L42>0,L42<=50),1,IF(AND(L42=0,L42<0),"-","-"))) -> - | M43: =IF((M42>50),3,IF(AND(M42>0,M42<=50),1,IF(AND(M42=0,M42<0),"-","-"))) -> - | N43: =IF((N42>50),3,IF(AND(N42>0,N42<=50),1,IF(AND(N42=0,N42<0),"-","-"))) -> - | O43: =IF((O42>50),3,IF(AND(O42>0,O42<=50),1,IF(AND(O42=0,O42<0),"-","-"))) -> - | P43: =IF((P42>50),3,IF(AND(P42>0,P42<=50),1,IF(AND(P42=0,P42<0),"-","-"))) -> -
...

Sheet PSO mapping
A4: Justification 1 | D4: Keywords mapping to Competency from resepctive CO | K4: Y or N
A5: PSO | B5: Competency | D5: CO1 | E5: CO2 | F5: CO3 | G5: CO4 | H5: CO5 | I5: CO6 | K5: CO1 | L5: CO2 | M5: CO3 | N5: CO4 | O5: CO5 | P5: CO6
A6: Professional Skills-The ability to comprehend, analyze and develop software and hardware systems and applications through research, in varying domains. | B6: Demonstrate the ability to analyze software, hardware system | D6: protocol | E6: protocol | F6: protocol | G6: protocol | H6: protocol | I6: protocol | K6: =IF(D6="","","Y") -> Y | L6: =IF(E6="","","Y") -> Y | M6: =IF(F6="","","Y") -> Y | N6: =IF(G6="","","Y") -> Y | O6: =IF(H6="","","Y") -> Y | P6: =IF(I6="","","Y") -> Y
B7: Demonstrate the ability to develop the software system or application | D7: model | E7: error control | F7: flow control | G7: socket | H7: applications | I7: security | K7: =IF(D7="","","Y") -> Y | L7: =IF(E7="","","Y") -> Y | M7: =IF(F7="","","Y") -> Y | N7: =IF(G7="","","Y") -> Y | O7: =IF(H7="","","Y") -> Y | P7: =IF(I7="","","Y") -> Y
B8: Demonstrate the ability to do research in computer science and engineering | D8: model | E8: contention | F8: routing | G8: congetsion | H8: applications | I8: IPSec | K8: =IF(D8="","","Y") -> Y | L8: =IF(E8="","","Y") -> Y | M8: =IF(F8="","","Y") -> Y | N8: =IF(G8="","","Y") -> Y | O8: =IF(H8="","","Y") -> Y | P8: =IF(I8="","","Y") -> Y
D9: No of competencies from given PSO1 mapped by COs | K9: =COUNTIF(K6:K8,"Y") -> 3 | L9: =COUNTIF(L6:L8,"Y") -> 3 | M9: =COUNTIF(M6:M8,"Y") -> 3 | N9: =COUNTIF(N6:N8,"Y") -> 3 | O9: =COUNTIF(O6:O8,"Y") -> 3 | P9: =COUNTIF(P6:P8,"Y") -> 3
D10: % of competencies from given PSO1 mapped by COs | K10: =100*K9/4 -> 75 | L10: =100*L9/4 -> 75 | M10: =100*M9/4 -> 75 | N10: =100*N9/4 -> 75 | O10: =100*O9/4 -> 75 | P10: =100*P9/4 -> 75
D11: Mapping strength of PSO1 of CO | K11: =IF((K10>=66),3,IF(AND(K10>=33,K10<66),2,IF(AND(K10>0,K10<33),1,"-"))) -> 3 | L11: =IF((L10>=66),3,IF(AND(L10>=33,L10<66),2,IF(AND(L10>0,L10<33),1,"-"))) -> 3 | M11: =IF((M10>=66),3,IF(AND(M10>=33,M10<66),2,IF(AND(M10>0,M10<33),1,"-"))) -> 3 | N11: =IF((N10>=66),3,IF(AND(N10>=33,N10<66),2,IF(AND(N10>0,N10<33),1,"-"))) -> 3 | O11: =IF((O10>=66),3,IF(AND(O10>=33,O10<66),2,IF(AND(O10>0,O10<33),1,"-"))) -> 3 | P11: =IF((P10>=66),3,IF(AND(P10>=33,P10<66),2,IF(AND(P10>0,P10<33),1,"-"))) -> 3
A12: Problem-Solving Skills- The ability to apply standard paradigms and strategies in software project development using open-ended programming environments to deliver a quality product. | B12: Demonstrate the ability to apply startegies for software project development | K12: =IF(D12="","","Y") | L12: =IF(E12="","","Y") | M12: =IF(F12="","","Y") | N12: =IF(G12="","","Y") | O12: =IF(H12="","","Y") | P12: =IF(I12="","","Y")
B13: Demonstrate the ability to apply tools for software project development | D13: Model | E13: CRC | F13: IP addressing | G13: routing | H13: application | I13: security | K13: =IF(D13="","","Y") -> Y | L13: =IF(E13="","","Y") -> Y | M13: =IF(F13="","","Y") -> Y | N13: =IF(G13="","","Y") -> Y | O13: =IF(H13="","","Y") -> Y | P13: =IF(I13="","","Y") -> Y
B14: Demonstrate the ability to use different programming paradigms. | D14: Model | E14: CRC | F14: IP addressing | G14: routing | H14: application | I14: security | K14: =IF(D14="","","Y") -> Y | L14: =IF(E14="","","Y") -> Y | M14: =IF(F14="","","Y") -> Y | N14: =IF(G14="","","Y") -> Y | O14: =IF(H14="","","Y") -> Y | P14: =IF(I14="","","Y") -> Y
D15: No of competencies from given PSO2 mapped by COs | K15: =COUNTIF(K12:K14,"Y") -> 2 | L15: =COUNTIF(L12:L14,"Y") -> 2 | M15: =COUNTIF(M12:M14,"Y") -> 2 | N15: =COUNTIF(N12:N14,"Y") -> 2 | O15: =COUNTIF(O12:O14,"Y") -> 2 | P15: =COUNTIF(P12:P14,"Y") -> 2
D16: % of competencies from given PSO2 mapped by COs | K16: =100*K15/4 -> 50 | L16: =100*L15/4 -> 50 | M16: =100*M15/4 -> 50 | N16: =100*N15/4 -> 50 | O16: =100*O15/4 -> 50 | P16: =100*P15/4 -> 50
D17: Mapping strength of PSO2 of CO | K17: =IF((K16>=66),3,IF(AND(K16>=33,K16<66),2,IF(AND(K16>0,K16<33),1,"-"))) -> 2 | L17: =IF((L16>=66),3,IF(AND(L16>=33,L16<66),2,IF(AND(L16>0,L16<33),1,"-"))) -> 2 | M17: =IF((M16>=66),3,IF(AND(M16>=33,M16<66),2,IF(AND(M16>0,M16<33),1,"-"))) -> 2 | N17: =IF((N16>=66),3,IF(AND(N16>=33,N16<66),2,IF(AND(N16>0,N16<33),1,"-"))) -> 2 | O17: =IF((O16>=66),3,IF(AND(O16>=33,O16<66),2,IF(AND(O16>0,O16<33),1,"-"))) -> 2 | P17: =IF((P16>=66),3,IF(AND(P16>=33,P16<66),2,IF(AND(P16>0,P16<33),1,"-"))) -> 2
A18: Successful Career and Entrepreneurship- adaptation of modern practical and systematic approaches in creating innovative solutions for a successful career, entrepreneurship, and a zest for higher studies. | B18: Demonstrate the ability to use modern practical approaches for creation of innovative solutions. | H18: application | I18: Secuity | K18: =IF(D18="","","Y") | L18: =IF(E18="","","Y") | M18: =IF(F18="","","Y") | N18: =IF(G18="","","Y") | O18: =IF(H18="","","Y") -> Y | P18: =IF(I18="","","Y") -> Y
B19: Demonstarte the ability to use modern practices to achieve zest for higher studies | K19: =IF(D19="","","Y") | L19: =IF(E19="","","Y") | M19: =IF(F19="","","Y") | N19: =IF(G19="","","Y") | O19: =IF(H19="","","Y") | P19: =IF(I19="","","Y")
B20: Demonstrate the ability to follow systematic approaches for becoming successful in career and entrepreneruship. | K20: =IF(D20="","","Y") | L20: =IF(E20="","","Y") | M20: =IF(F20="","","Y") | N20: =IF(G20="","","Y") | O20: =IF(H20="","","Y") | P20: =IF(I20="","","Y")
D21: No of competencies from given PSO3 mapped by COs | K21: =COUNTIF(K18:K20,"Y") -> 0 | L21: =COUNTIF(L18:L20,"Y") -> 0 | M21: =COUNTIF(M18:M20,"Y") -> 0 | N21: =COUNTIF(N18:N20,"Y") -> 0 | O21: =COUNTIF(O18:O20,"Y") -> 1 | P21: =COUNTIF(P18:P20,"Y") -> 1
D22: % of competencies from given PSO3 mapped by COs | K22: =100*K21/4 -> 0 | L22: =100*L21/4 -> 0 | M22: =100*M21/4 -> 0 | N22: =100*N21/4 -> 0 | O22: =100*O21/4 -> 25 | P22: =100*P21/4 -> 25
D23: Mapping strength of PSO3 of CO | K23: =IF((K22>=66),3,IF(AND(K22>=33,K22<66),2,IF(AND(K22>0,K22<33),1,"-"))) -> - | L23: =IF((L22>=66),3,IF(AND(L22>=33,L22<66),2,IF(AND(L22>0,L22<33),1,"-"))) -> - | M23: =IF((M22>=66),3,IF(AND(M22>=33,M22<66),2,IF(AND(M22>0,M22<33),1,"-"))) -> - | N23: =IF((N22>=66),3,IF(AND(N22>=33,N22<66),2,IF(AND(N22>0,N22<33),1,"-"))) -> - | O23: =IF((O22>=66),3,IF(AND(O22>=33,O22<66),2,IF(AND(O22>0,O22<33),1,"-"))) -> 1 | P23: =IF((P22>=66),3,IF(AND(P22>=33,P22<66),2,IF(AND(P22>0,P22<33),1,"-"))) -> 1

Sheet Examination
B1: D Y Patil International University, Akurdi Pune
B2: Name of School
A4: Course Outcome attainment Calculations through Direct Method
A5: Subject Name
A7: Class | F7: Academic Year
A9: Total Number of Students | F9: =COUNTIF(A23:A323,">0") -> 24
A11: Threshhold for attainment level | K11: 60
C13: Reference : Number of students above threshold
C14: # of student >= of out of marks | F14: =COUNTIF(F23:F323,">="&F21) -> 11 | G14: =COUNTIF(G23:G323,">="&G21) -> 8 | H14: =COUNTIF(H23:H323,">="&H21) -> 11 | I14: =COUNTIF(I23:I323,">="&I21) -> 6 | J14: =COUNTIF(J23:J323,">="&J21) -> 19 | K14: =COUNTIF(K23:K323,">="&K21) -> 12
C16: Reference : % of Number of students above threshold
C17: % of students above threshhold | F17: =100*F14/$F$9 -> 45.833333 | G17: =100*G14/$F$9 -> 33.333333 | H17: =100*H14/$F$9 -> 45.833333 | I17: =100*I14/$F$9 -> 25 | J17: =100*J14/$F$9 -> 79.166667 | K17: =100*K14/$F$9 -> 50
A19: Out of | F19: 15 | G19: 15 | H19: 15 | I19: 15 | J19: 15 | K19: 15
A20: Sr No | B20: PRN No | C20: Name | F20: CO Assessment
A21: Fraction of Out of marks with respect to Threshold | F21: =IFERROR(F19*$K$11/100,"") -> 9 | G21: =IFERROR(G19*$K$11/100,"") -> 9 | H21: =IFERROR(H19*$K$11/100,"") -> 9 | I21: =IFERROR(I19*$K$11/100,"") -> 9 | J21: =IFERROR(J19*$K$11/100,"") -> 9 | K21: =IFERROR(K19*$K$11/100,"") -> 9
F22: CO1 | G22: CO2 | H22: CO3 | I22: CO4 | J22: CO5 | K22: CO6
A23: =IF(B23<>"", COUNTA($B$23:B23), "") -> 1 | B23: 3001 | C23: NETAM RITESH PRAKASH | F23: 10 | G23: 9 | H23: 14 | I23: 10 | J23: 10 | K23: 11
A24: =IF(B24<>"", COUNTA($B$23:B24), "") -> 2 | B24: 3002 | C24: KAMBLE AMEYA DNYANESHWAR | F24: 9 | G24: 6 | H24: 8 | I24: 10 | J24: 14 | K24: 9
A25: =IF(B25<>"", COUNTA($B$23:B25), "") -> 3 | B25: 3003 | C25: TEKAM SANJIVANI SURESH | F25: 9 | G25: 8 | H25: 5 | I25: 7 | J25: 14 | K25: 5
A26: =IF(B26<>"", COUNTA($B$23:B26), "") -> 4 | B26: 3004 | C26: KUWAR ABHIJEET VIJAYSING | F26: 8 | G26: 7 | H26: 5 | I26: 8 | J26: 10 | K26: 5
A27: =IF(B27<>"", COUNTA($B$23:B27), "") -> 5 | B27: 3005 | C27: ROHAN SUNIL BORSE | F27: 10 | G27: 14 | H27: 11 | I27: 8 | J27: 19 | K27: 11
A28: =IF(B28<>"", COUNTA($B$23:B28), "") -> 6 | B28: 3006 | C28: GALANDE NIKHIL SHRINIVAS | F28: 8 | G28: 5 | H28: 7 | I28: 8 | J28: 10 | K28: 7
A29: =IF(B29<>"", COUNTA($B$23:B29), "") -> 7 | B29: 3007 | C29: FAZAL S | F29: 9 | G29: 6 | H29: 12 | I29: 13 | J29: 9 | K29: 12
A30: =IF(B30<>"", COUNTA($B$23:B30), "") -> 8 | B30: 3008 | C30: TEJARAM CHOUDHARY | F30: 8 | G30: 7 | H30: 5 | I30: 5 | J30: 10 | K30: 5
A31: =IF(B31<>"", COUNTA($B$23:B31), "") -> 9 | B31: 3009 | C31: GORULE GURUNATH VILAS | F31: 7 | G31: 7 | H31: 15 | I31: 5 | J31: 13 | K31: 15
A32: =IF(B32<>"", COUNTA($B$23:B32), "") -> 10 | B32: 3010 | C32: KADAM SUJAL PRABHAKAR | F32: 12 | G32: 9 | H32: 6 | I32: 6 | J32: 9 | K32: 6
A33: =IF(B33<>"", COUNTA($B$23:B33), "") -> 11 | B33: 3011 | C33: JAWALE PRATHAM RAJESH | F33: 8 | G33: 6 | H33: 7 | I33: 15 | J33: 10 | K33: 7
A34: =IF(B34<>"", COUNTA($B$23:B34), "") -> 12 | B34: 3012 | C34: TADAVI NIHAL KURBAN | F34: 8 | G34: 9 | H34: 11 | I34: 6 | J34: 9 | K34: 11
... A46: =IF(B46<>"", COUNTA($B$23:B46), "") -> 24 | B46: 3024 | C46: INGAWALE PRANJALI WAMANRAO | F46: 8 | G46: 5 | H46: 7 | I46: 5 | J46: 8 | K46: 7
A47: =IF(B47<>"", COUNTA($B$23:B47), "")
A48: =IF(B48<>"", COUNTA($B$23:B48), "")
A49: =IF(B49<>"", COUNTA($B$23:B49), "")
A50: =IF(B50<>"", COUNTA($B$23:B50), "")
A51: =IF(B51<>"", COUNTA($B$23:B51), "")
A52: =IF(B52<>"", COUNTA($B$23:B52), "")
A53: =IF(B53<>"", COUNTA($B$23:B53), "")
A54: =IF(B54<>"", COUNTA($B$23:B54), "")
A55: =IF(B55<>"", COUNTA($B$23:B55), "")
A56: =IF(B56<>"", COUNTA($B$23:B56), "")
A57: =IF(B57<>"", COUNTA($B$23:B57), "")
A58: =IF(B58<>"", COUNTA($B$23:B58), "")
...

Sheet Course End Survey
B1: D Y Patil International University, Akurdi Pune
B2: Name of School
A4: Course Outcome attainment Calculations through Indirect Method
C6: CO1 | D6: CO2 | E6: CO3 | F6: CO4 | G6: CO5 | H6: CO6
A7: Count of each level | B7: 1 | C7: =COUNTIF(C20:C320,"Slight") -> 0 | D7: =COUNTIF(D20:D320,"Slight") -> 6 | E7: =COUNTIF(E20:E320,"Slight") -> 6 | F7: =COUNTIF(F20:F320,"Slight") -> 11 | G7: =COUNTIF(G20:G320,"Slight") -> 0 | H7: =COUNTIF(H20:H320,"Slight") -> 0
B8: 2 | C8: =COUNTIF(C20:C320,"Moderate") -> 9 | D8: =COUNTIF(D20:D320,"Moderate") -> 7 | E8: =COUNTIF(E20:E320,"Moderate") -> 5 | F8: =COUNTIF(F20:F320,"Moderate") -> 0 | G8: =COUNTIF(G20:G320,"Moderate") -> 8 | H8: =COUNTIF(H20:H320,"Moderate") -> 7
B9: 3 | C9: =COUNTIF(C20:C320,"Substantial") -> 15 | D9: =COUNTIF(D20:D320,"Substantial") -> 11 | E9: =COUNTIF(E20:E320,"Substantial") -> 13 | F9: =COUNTIF(F20:F320,"Substantial") -> 13 | G9: =COUNTIF(G20:G320,"Substantial") -> 16 | H9: =COUNTIF(H20:H320,"Substantial") -> 17
A11: % of students | B11: 1 | C11: =C7*100/$B$19 -> 0 | D11: =D7*100/$B$19 -> 25 | E11: =E7*100/$B$19 -> 25 | F11: =F7*100/$B$19 -> 45.833333 | G11: =G7*100/$B$19 -> 0 | H11: =H7*100/$B$19 -> 0
B12: 2 | C12: =C8*100/$B$19 -> 37.5 | D12: =D8*100/$B$19 -> 29.166667 | E12: =E8*100/$B$19 -> 20.833333 | F12: =F8*100/$B$19 -> 0 | G12: =G8*100/$B$19 -> 33.333333 | H12: =H8*100/$B$19 -> 29.166667
B13: 3 | C13: =C9*100/$B$19 -> 62.5 | D13: =D9*100/$B$19 -> 45.833333 | E13: =E9*100/$B$19 -> 54.166667 | F13: =F9*100/$B$19 -> 54.166667 | G13: =G9*100/$B$19 -> 66.666667 | H13: =H9*100/$B$19 -> 70.833333
A15: Overall Indirect % | C15: =(C11*0.33+C12*0.67+C13*1) -> 87.625 | D15: =(D11*0.33+D12*0.67+D13*1) -> 73.625 | E15: =(E11*0.33+E12*0.67+E13*1) -> 76.375 | F15: =(F11*0.33+F12*0.67+F13*1) -> 69.291667 | G15: =(G11*0.33+G12*0.67+G13*1) -> 89 | H15: =(H11*0.33+H12*0.67+H13*1) -> 90.375
A18: Sr No | C18: CO1 | D18: CO2 | E18: CO3 | F18: CO4 | G18: CO5 | H18: CO6
A19: No. of Students | B19: =COUNTIF(A20:A320,">0") -> 24
A20: =IF(C20<>"", COUNTA($C$20:C20), "") -> 1 | C20: Moderate | D20: Moderate | E20: Moderate | F20: Slight | G20: Moderate | H20: Substantial
A21: =IF(C21<>"", COUNTA($C$20:C21), "") -> 2 | C21: Substantial | D21: Substantial | E21: Substantial | F21: Substantial | G21: Substantial | H21: Substantial
A22: =IF(C22<>"", COUNTA($C$20:C22), "") -> 3 | C22: Substantial | D22: Substantial | E22: Substantial | F22: Substantial | G22: Substantial | H22: Substantial
A23: =IF(C23<>"", COUNTA($C$20:C23), "") -> 4 | C23: Substantial | D23: Substantial | E23: Substantial | F23: Substantial | G23: Substantial | H23: Substantial
A24: =IF(C24<>"", COUNTA($C$20:C24), "") -> 5 | C24: Moderate | D24: Moderate | E24: Moderate | F24: Slight | G24: Moderate | H24: Moderate
A25: =IF(C25<>"", COUNTA($C$20:C25), "") -> 6 | C25: Substantial | D25: Moderate | E25: Moderate | F25: Slight | G25: Substantial | H25: Substantial
A26: =IF(C26<>"", COUNTA($C$20:C26), "") -> 7 | C26: Moderate | D26: Substantial | E26: Substantial | F26: Substantial | G26: Moderate | H26: Moderate
A27: =IF(C27<>"", COUNTA($C$20:C27), "") -> 8 | C27: Substantial | D27: Substantial | E27: Substantial | F27: Substantial | G27: Substantial | H27: Substantial
A28: =IF(C28<>"", COUNTA($C$20:C28), "") -> 9 | C28: Moderate | D28: Substantial | E28: Substantial | F28: Substantial | G28: Moderate | H28: Moderate
A29: =IF(C29<>"", COUNTA($C$20:C29), "") -> 10 | C29: Substantial | D29: Substantial | E29: Substantial | F29: Substantial | G29: Substantial | H29: Substantial
A30: =IF(C30<>"", COUNTA($C$20:C30), "") -> 11 | C30: Moderate | D30: Substantial | E30: Substantial | F30: Substantial | G30: Moderate | H30: Moderate
A31: =IF(C31<>"", COUNTA($C$20:C31), "") -> 12 | C31: Substantial | D31: Substantial | E31: Substantial | F31: Substantial | G31: Substantial | H31: Substantial
... A43: =IF(C43<>"", COUNTA($C$20:C43), "") -> 24 | C43: Substantial | D43: Substantial | E43: Substantial | F43: Substantial | G43: Substantial | H43: Substantial
A44: =IF(C44<>"", COUNTA($C$20:C44), "")
A45: =IF(C45<>"", COUNTA($C$20:C45), "")
A46: =IF(C46<>"", COUNTA($C$20:C46), "")
A47: =IF(C47<>"", COUNTA($C$20:C47), "")
A48: =IF(C48<>"", COUNTA($C$20:C48), "")
A49: =IF(C49<>"", COUNTA($C$20:C49), "")
A50: =IF(C50<>"", COUNTA($C$20:C50), "")
A51: =IF(C51<>"", COUNTA($C$20:C51), "")
A52: =IF(C52<>"", COUNTA($C$20:C52), "")
A53: =IF(C53<>"", COUNTA($C$20:C53), "")
A54: =IF(C54<>"", COUNTA($C$20:C54), "")
A55: =IF(C55<>"", COUNTA($C$20:C55), "")
... A320: =IF(C320<>"", COUNTA($C$20:C320), "")

Sheet Concurrent Assessment
B1: D Y Patil International University, Akurdi Pune
B2: Name of the School
B3: Student Assessment Semester --- - AY ------
A4: Subject Name (Course Code)
A5: Sr No | B5: PRN No. | C5: Name of Student | D5: Assessment 1 | F5: Practical (Conduction + oral) | G5: Presentation | H5: Scaled to 30 | I5: Mid Sem Marks | J5: Total Marks
D6: Unit Test | E6: Assignment
D7: 5 | E7: 5 | F7: 30 | G7: 20 | H7: 30 | I7: 20 | J7: 50
D8: CO1 | E8: CO1 | F8: CO1 to CO6 | G8: CO2 | I8: CO1 & CO2
A9: 1 | B9: 3001 | C9: NETAM RITESH PRAKASH | D9: 2 | E9: 3 | F9: 28 | G9: 17 | H9: =SUM(D9:G9)/2 -> 25 | I9: 9 | J9: =ROUND(H9+I9,0) -> 34
A10: 2 | B10: 3002 | C10: KAMBLE AMEYA DNYANESHWAR | D10: AB | E10: 3 | F10: 23 | G10: 14 | H10: =SUM(D10:G10)/2 -> 20 | I10: 5 | J10: =ROUND(H10+I10,0) -> 25
A11: 3 | B11: 3003 | C11: TEKAM SANJIVANI SURESH | D11: 1 | E11: 3 | F11: 23 | G11: 16 | H11: =SUM(D11:G11)/2 -> 21.5 | I11: 7 | J11: =ROUND(H11+I11,0) -> 29
A12: 4 | B12: 3004 | C12: KUWAR ABHIJEET VIJAYSING | D12: 3 | E12: 0 | F12: 23 | G12: 16 | H12: =SUM(D12:G12)/2 -> 21 | I12: 5 | J12: =ROUND(H12+I12,0) -> 26
A13: 5 | B13: 3005 | C13: ROHAN SUNIL BORSE | D13: 4 | E13: 5 | F13: 23 | G13: 14 | H13: =SUM(D13:G13)/2 -> 23 | I13: 14 | J13: =ROUND(H13+I13,0) -> 37
A14: 6 | B14: 3006 | C14: GALANDE NIKHIL SHRINIVAS | D14: AB | E14: 0 | F14: 23 | G14: 18 | H14: =SUM(D14:G14)/2 -> 20.5 | I14: 3 | J14: =ROUND(H14+I14,0) -> 24
A15: 7 | B15: 3007 | C15: FAZAL S | D15: 1 | E15: 4 | F15: 26 | G15: 14 | H15: =SUM(D15:G15)/2 -> 22.5 | I15: 5 | J15: =ROUND(H15+I15,0) -> 28
A16: 8 | B16: 3008 | C16: TEJARAM CHOUDHARY | D16: 1 | E16: 0 | F16: 23 | G16: 15 | H16: =SUM(D16:G16)/2 -> 19.5 | I16: 5 | J16: =ROUND(H16+I16,0) -> 25
A17: 9 | B17: 3009 | C17: GORULE GURUNATH VILAS | D17: 3 | E17: 5 | F17: 24 | G17: 15 | H17: =SUM(D17:G17)/2 -> 23.5 | I17: 4 | J17: =ROUND(H17+I17,0) -> 28
A18: 10 | B18: 3010 | C18: KADAM SUJAL PRABHAKAR | D18: 1 | E18: 0 | F18: 23 | G18: 17 | H18: =SUM(D18:G18)/2 -> 20.5 | I18: 11 | J18: =ROUND(H18+I18,0) -> 32
A19: 11 | B19: 3011 | C19: JAWALE PRATHAM RAJESH | D19: 1 | E19: 4 | F19: 26 | G19: 15 | H19: =SUM(D19:G19)/2 -> 23 | I19: 4 | J19: =ROUND(H19+I19,0) -> 27
A20: 12 | B20: 3012 | C20: TADAVI NIHAL KURBAN | D20: 2 | E20: 4 | F20: 24 | G20: 16 | H20: =SUM(D20:G20)/2 -> 23 | I20: 7 | J20: =ROUND(H20+I20,0) -> 30
A21: 13 | B21: 3013 | C21: DUMBHARE DEVASHISH ASHOK | D21: 2 | E21: 3 | F21: 24 | G21: 16 | H21: =SUM(D21:G21)/2 -> 22.5 | I21: 10 | J21: =ROUND(H21+I21,0) -> 33
A22: 14 | B22: 3014 | C22: JAGTAP ATHARVA AJIT | D22: 2 | E22: 0 | F22: 26 | G22: 17 | H22: =SUM(D22:G22)/2 -> 22.5 | I22: 5 | J22: =ROUND(H22+I22,0) -> 28
A23: 15 | B23: 3015 | C23: DIVYA MANKOTIA | D23: 1 | E23: 3 | F23: 23 | G23: 17 | H23: =SUM(D23:G23)/2 -> 22 | I23: 6 | J23: =ROUND(H23+I23,0) -> 28
A24: 16 | B24: 3016 | C24: MODI RAINEE | D24: 1 | E24: 3 | F24: 23 | G24: 15 | H24: =SUM(D24:G24)/2 -> 21 | I24: 6 | J24: =ROUND(H24+I24,0) -> 27
A25: 17 | B25: 3017 | C25: KAMBLE TEJASWINI PRAVIN | D25: 4 | E25: 4 | F25: 27 | G25: 18 | H25: =SUM(D25:G25)/2 -> 26.5 | I25: 15 | J25: =ROUND(H25+I25,0) -> 42
A26: 18 | B26: 3018 | C26: BHARSKAR TEJAS VISHNU | D26: 2 | E26: 3 | F26: 23 | G26: 17 | H26: =SUM(D26:G26)/2 -> 22.5 | I26: 4 | J26: =ROUND(H26+I26,0) -> 27
... A32: 24 | B32: 3024 | C32: INGAWALE PRANJALI WAMANRAO | D32: 2 | E32: 0 | F32: 23 | G32: 16 | H32: =SUM(D32:G32)/2 -> 20.5 | I32: 3 | J32: =ROUND(H32+I32,0) -> 24

Sheet End Sem
B1: D Y Patil International University, Akurdi Pune
B2: Name of the School
B3: Student Assessment Semester --- - AY ------
A4: Subject Name (Course Code)
A5: End Sem Examination
A6: Course Outcome | D6: CO1 | E6: CO2 | F6: CO3 | G6: CO4 | H6: CO4 | I6: CO5 | J6: CO3 | K6: CO3 | L6: CO3 | M6: CO5 | N6: CO5 | O6: CO5 | P6: CO4 | Q6: CO4 | R6: CO6
A7: Question | D7: 1 | E7: 2 | F7: 3 | G7: 4 | H7: 5 | I7: 6 | J7: 7 | K7: 8 | L7: 9 | M7: 10 | N7: 11 | O7: 12 | P7: 13A | Q7: 13B
A8: 1 | B8: 3001 | C8: NETAM RITESH PRAKASH | F8: 1 | G8: 1 | H8: 1 | J8: 6 | K8: 2 | N8: 5 | P8: 3 | R8: 11
A9: 2 | B9: 3002 | C9: KAMBLE AMEYA DNYANESHWAR | G9: 2 | J9: 3 | N9: 7 | O9: 2 | P9: 3 | R9: 9
A10: 3 | B10: 3003 | C10: TEKAM SANJIVANI SURESH | M10: 2 | N10: 7 | P10: 2 | R10: 5
A11: 4 | B11: 3004 | C11: KUWAR ABHIJEET VIJAYSING | D11: 0 | F11: 0 | M11: 2 | N11: 3 | P11: 3 | R11: 5
A12: 5 | B12: 3005 | C12: ROHAN SUNIL BORSE | F12: 4 | G12: 2 | I12: 3 | K12: 2 | L12: 0 | M12: 6 | N12: 6 | P12: 1 | R12: 11
A13: 6 | B13: 3006 | C13: GALANDE NIKHIL SHRINIVAS | F13: 1 | G13: 1 | I13: 2 | K13: 1 | L13: 0 | M13: 2 | N13: 1 | Q13: 2 | R13: 7
A14: 7 | B14: 3007 | C14: FAZAL S | F14: 3 | I14: 1 | K14: 4 | N14: 3 | Q14: 8 | R14: 12
A15: 8 | B15: 3008 | C15: TEJARAM CHOUDHARY | N15: 5 | R15: 5
A16: 9 | B16: 3009 | C16: GORULE GURUNATH VILAS | F16: 3 | I16: 2 | J16: 5 | L16: 2 | N16: 6 | Q16: 0 | R16: 15
A17: 10 | B17: 3010 | C17: KADAM SUJAL PRABHAKAR | F17: 1 | G17: 1 | I17: 1 | L17: 0 | N17: 2 | O17: 1 | Q17: 0 | R17: 6
A18: 11 | B18: 3011 | C18: JAWALE PRATHAM RAJESH | F18: 1 | G18: 0 | I18: 1 | J18: 1 | N18: 2 | O18: 2 | Q18: 10 | R18: 7
A19: 12 | B19: 3012 | C19: TADAVI NIHAL KURBAN | F19: 4 | G19: 1 | I19: 2 | J19: 2 | N19: 2 | P19: 0 | R19: 11
A20: 13 | B20: 3013 | C20: DUMBHARE DEVASHISH ASHOK | F20: 4 | G20: 1 | I20: 2 | N20: 7 | O20: 6 | Q20: 10 | R20: 9
A21: 14 | B21: 3014 | C21: JAGTAP ATHARVA AJIT | G21: 1 | H21: 1 | I21: 2 | J21: 2 | N21: 5 | O21: 3 | R21: 7
A22: 15 | B22: 3015 | C22: DIVYA MANKOTIA | F22: 1 | G22: 0 | I22: 2 | J22: 5 | N22: 7 | O22: 2 | P22: 1 | R22: 11
A23: 16 | B23: 3016 | C23: MODI RAINEE | F23: 1 | G23: 0 | I23: 1 | J23: 3 | M23: 0 | N23: 7 | P23: 1 | R23: 9
A24: 17 | B24: 3017 | C24: KAMBLE TEJASWINI PRAVIN | D24: 3 | F24: 4 | I24: 1 | J24: 3 | L24: 3 | N24: 4 | O24: 2 | R24: 15
A25: 18 | B25: 3018 | C25: BHARSKAR TEJAS VISHNU | D25: 2 | F25: 0 | L25: 2 | N25: 1 | R25: 7
A26: 19 | B26: 3019 | C26: WARE PRASAD DHONDIRAM | F26: 2 | I26: 1 | R26: 7
A27: 20 | B27: 3020 | C27: ILHE SHREYASH NAMDEV | D27: 2 | G27: 2 | H27: 0 | J27: 2 | K27: 2 | N27: 4 | O27: 4 | P27: 3 | R27: 9
A28: 21 | B28: 3021 | C28: DURVESH VISHWAS PATIL | F28: 1 | G28: 0 | K28: 0 | R28: 6
A29: 22 | B29: 3022 | C29: MAHAJAN GAURAV NAMDEO | E29: 2 | F29: 4 | I29: 4 | K29: 5 | L29: 2 | P29: 1 | R29: 16
A30: 23 | B30: 3023 | C30: TAGADE ANUSHKA AJAYKUMAR | F30: 0 | G30: 0 | I30: 0 | N30: 1 | R30: 5
A31: 24 | B31: 3024 | C31: INGAWALE PRANJALI WAMANRAO | K31: 0 | L31: 2 | M31: 0 | N31: 2 | O31: 1 | P31: 0 | R31: 7

Sheet CO-wise evaluation
A1: D Y Patil International University, Akurdi Pune
A2: Name of the School
A3: Student Assessment Semester --- - AY ------
A4: Subject Name (Course Code)
A5: Sr No | B5: PRN | C5: Name of Student | D5: Course Outcome
D6: CO1 | E6: CO2 | F6: CO3 | G6: CO4 | H6: CO5 | I6: CO6
D7: 20 | E7: 20 | F7: 20 | G7: 20 | H7: 20 | I7: 20
A8: 1 | B8: 3001 | C8: NETAM RITESH PRAKASH | D8: 10 | E8: 9 | F8: 14 | G8: 10 | H8: 10 | I8: 11
A9: 2 | B9: 3002 | C9: KAMBLE AMEYA DNYANESHWAR | D9: 9 | E9: 6 | F9: 8 | G9: 10 | H9: 14 | I9: 9
A10: 3 | B10: 3003 | C10: TEKAM SANJIVANI SURESH | D10: 9 | E10: 8 | F10: 5 | G10: 7 | H10: 14 | I10: 5
A11: 4 | B11: 3004 | C11: KUWAR ABHIJEET VIJAYSING | D11: 8 | E11: 7 | F11: 5 | G11: 8 | H11: 10 | I11: 5
A12: 5 | B12: 3005 | C12: ROHAN SUNIL BORSE | D12: 10 | E12: 14 | F12: 11 | G12: 8 | H12: 19 | I12: 11
A13: 6 | B13: 3006 | C13: GALANDE NIKHIL SHRINIVAS | D13: 8 | E13: 5 | F13: 7 | G13: 8 | H13: 10 | I13: 7
A14: 7 | B14: 3007 | C14: FAZAL S | D14: 9 | E14: 6 | F14: 12 | G14: 13 | H14: 9 | I14: 12
A15: 8 | B15: 3008 | C15: TEJARAM CHOUDHARY | D15: 8 | E15: 7 | F15: 5 | G15: 5 | H15: 10 | I15: 5
A16: 9 | B16: 3009 | C16: GORULE GURUNATH VILAS | D16: 7 | E16: 7 | F16: 15 | G16: 5 | H16: 13 | I16: 15
A17: 10 | B17: 3010 | C17: KADAM SUJAL PRABHAKAR | D17: 12 | E17: 9 | F17: 6 | G17: 6 | H17: 9 | I17: 6
A18: 11 | B18: 3011 | C18: JAWALE PRATHAM RAJESH | D18: 8 | E18: 6 | F18: 7 | G18: 15 | H18: 10 | I18: 7
A19: 12 | B19: 3012 | C19: TADAVI NIHAL KURBAN | D19: 8 | E19: 9 | F19: 11 | G19: 6 | H19: 9 | I19: 11
... A31: 24 | B31: 3024 | C31: INGAWALE PRANJALI WAMANRAO | D31: 8 | E31: 5 | F31: 7 | G31: 5 | H31: 8 | I31: 7
